Workbook

Sheet Read_Me
A1: PROJECT 06 · FP&A MODEL
A2: Real City of Austin FY2026 operating-budget pacing plus a clearly labeled synthetic corporate scenario model.
A4: Purpose | B4: Demonstrate budget-versus-actual analysis, pacing, variance drivers, scenarios, and Excel delivery.
A5: Public source | B5: City of Austin Program Budget Operating Budget Vs Expense Raw Data, dataset g5k8-8sud.
A6: Snapshot | B6: FY2026 through Q3; 57,267 source rows.
A7: Pacing boundary | B7: Expected spend to date is annual budget multiplied by elapsed quarter share. It is a monitoring proxy, not an accounting forecast.
A8: Known source caveat | B8: Personnel budgets and actuals can appear in different leave/pay objects. Zero-budget spend is retained for review, not automatically called an overrun.
A9: Corporate model | B9: The Corporate_Plan and Scenario_Assumptions sheets are seeded synthetic demonstrations and are not City of Austin data.
A10: How to use | B10: Change the three yellow assumption cells. Scenario formulas and dashboard metrics recalculate automatically in Excel.

Sheet Austin_Executive
A1: CITY OF AUSTIN · BUDGET PACING
A2: Expense pacing through Q3. Positive pace variance means expenditures are above a straight-line 75% benchmark.
A4: Annual budget | D4: Expenditures to date | G4: Utilization
A5: 8.1019905e+09 | D5: 6021243202 | G5: 0.74318073
A7: Pace variance | D7: Remaining budget | G7: Departments above pace
A8: -55249640 | D8: 2.0807473e+09 | G8: 6
A11: dept_rollup_name | B11: budget | C11: expenditures
A12: Austin Energy | B12: 1611344198 | C12: 1.2017006e+09
A13: Austin Water | B13: 931124230 | C13: 7.2564289e+08
A14: Aviation | B14: 650840976 | C14: 362072058
A15: Enterprise Debt Service | B15: 576232647 | C15: 5.1796033e+08
A16: Police | B16: 528637858 | C16: 4.2912495e+08
A17: Nondepartmental | B17: 439874669 | C17: 4.225019e+08
A18: Human Resources | B18: 385842777 | C18: 3.2193864e+08
A19: Public Works | B19: 310825661 | C19: 2.2381948e+08
A20: Austin Convention Center | B20: 286684067 | C20: 2.0579499e+08
A21: General Obligation Debt Service | B21: 283886060 | C21: 79034997
A22: Fire | B22: 269946011 | C22: 2.2871341e+08
A23: Communications & Technology Management | B23: 166779193 | C23: 1.3280532e+08

Sheet Departments
A1: Departments
A2: Reviewed output generated by build_finance.py.
A4: dept_rollup_name | B4: budget | C4: expenditures | D4: source_lines | E4: elapsed_pct | F4: expected_spend_to_date | G4: remaining_budget | H4: utilization_pct | I4: pace_variance | J4: pace_gap_pct_points | K4: linear_run_rate_proxy | L4: projected_variance_proxy | M4: pace_status
A5: Austin Energy | B5: 1611344198 | C5: 1.2017006e+09 | D5: 6994 | E5: 75 | F5: 1.2085081e+09 | G5: 4.0964363e+08 | H5: 74.577521 | I5: -6807584 | J5: -0.42247858 | K5: 1.6022674e+09 | L5: -9076778.7 | M5: Near pace
A6: Austin Water | B6: 931124230 | C6: 7.2564289e+08 | D6: 6933 | E6: 75 | F6: 6.9834317e+08 | G6: 2.0548134e+08 | H6: 77.93191 | I6: 27299722 | J6: 2.9319097 | K6: 9.6752386e+08 | L6: 36399629 | M6: Near pace
A7: Aviation | B7: 650840976 | C7: 362072058 | D7: 1772 | E7: 75 | F7: 488130732 | G7: 288768918 | H7: 55.631417 | I7: -126058674 | J7: -19.368583 | K7: 482762744 | L7: -168078232 | M7: Below pace
A8: Enterprise Debt Service | B8: 576232647 | C8: 5.1796033e+08 | D8: 26 | E8: 75 | F8: 4.3217449e+08 | G8: 58272322 | H8: 89.887362 | I8: 85785840 | J8: 14.887362 | K8: 6.9061377e+08 | L8: 1.1438112e+08 | M8: Above pace
A9: Police | B9: 528637858 | C9: 4.2912495e+08 | D9: 4480 | E9: 75 | F9: 3.9647839e+08 | G9: 99512903 | H9: 81.1756 | I9: 32646561 | J9: 6.1756003 | K9: 5.7216661e+08 | L9: 43528748 | M9: Above pace
A10: Nondepartmental | B10: 439874669 | C10: 4.225019e+08 | D10: 42 | E10: 75 | F10: 3.29906e+08 | G10: 17372770 | H10: 96.050518 | I10: 92595897 | J10: 21.050518 | K10: 5.6333587e+08 | L10: 1.234612e+08 | M10: Above pace
A11: Human Resources | B11: 385842777 | C11: 3.2193864e+08 | D11: 754 | E11: 75 | F11: 2.8938208e+08 | G11: 63904137 | H11: 83.437778 | I11: 32556557 | J11: 8.437778 | K11: 4.2925152e+08 | L11: 43408743 | M11: Above pace
A12: Public Works | B12: 310825661 | C12: 2.2381948e+08 | D12: 3853 | E12: 75 | F12: 2.3311925e+08 | G12: 87006186 | H12: 72.008043 | I12: -9299770.7 | J12: -2.9919572 | K12: 2.9842597e+08 | L12: -12399694 | M12: Near pace
A13: Austin Convention Center | B13: 286684067 | C13: 2.0579499e+08 | D13: 1488 | E13: 75 | F13: 2.1501305e+08 | G13: 80889077 | H13: 71.784593 | I13: -9218060 | J13: -3.2154072 | K13: 2.7439332e+08 | L13: -12290747 | M13: Near pace
A14: General Obligation Debt Service | B14: 283886060 | C14: 79034997 | D14: 7 | E14: 75 | F14: 212914545 | G14: 2.0485106e+08 | H14: 27.840394 | I14: -1.3387955e+08 | J14: -47.159606 | K14: 1.0538e+08 | L14: -1.7850606e+08 | M14: Below pace
A15: Fire | B15: 269946011 | C15: 2.2871341e+08 | D15: 1621 | E15: 75 | F15: 2.0245951e+08 | G15: 41232601 | H15: 84.725612 | I15: 26253902 | J15: 9.725612 | K15: 3.0495121e+08 | L15: 35005202 | M15: Above pace
A16: Communications & Technology Management | B16: 166779193 | C16: 1.3280532e+08 | D16: 1659 | E16: 75 | F16: 1.2508439e+08 | G16: 33973878 | H16: 79.629427 | I16: 7720920.4 | J16: 4.6294266 | K16: 1.7707375e+08 | L16: 10294560 | M16: Near pace
... A42: Austin Transportation | B42: 15700 | C42: -1539035 | D42: 2 | E42: 75 | F42: 11775 | G42: 1554735 | H42: -9802.7709 | I42: -1550810 | J42: -9877.7709 | K42: -2052046.7 | L42: -2067746.7 | M42: Below pace
A43: Communications & Public Information | B43: 0 | C43: 0 | D43: 312 | E43: 75 | F43: 0 | G43: 0 | I43: 0 | K43: 0 | L43: 0 | M43: Review: non-positive budget
A44: Information Security Office | B44: 0 | C44: -142238.95 | D44: 127 | E44: 75 | F44: 0 | G44: 142238.95 | I44: -142238.95 | K44: -189651.93 | L44: -189651.93 | M44: Review: non-positive budget

Sheet Funds
A1: Funds
A2: Reviewed output generated by build_finance.py.
A4: dept_rollup_name | B4: fund_name | C4: budget | D4: expenditures | E4: source_lines | F4: elapsed_pct | G4: expected_spend_to_date | H4: remaining_budget | I4: utilization_pct | J4: pace_variance | K4: pace_gap_pct_points | L4: linear_run_rate_proxy | M4: projected_variance_proxy | N4: pace_status
A5: Austin Energy | B5: Austin Energy Fund | C5: 1384655791 | D5: 1.0725243e+09 | E5: 6984 | F5: 75 | G5: 1.0384918e+09 | H5: 3.1213151e+08 | I5: 77.457827 | J5: 34032439 | K5: 2.4578266 | L5: 1.4300324e+09 | M5: 45376585 | N5: Near pace
A6: Police | B6: General Fund | C6: 525359250 | D6: 4.2826555e+08 | E6: 4427 | F6: 75 | G6: 3.9401944e+08 | H6: 97093700 | I6: 81.518608 | J6: 34246112 | K6: 6.5186085 | L6: 5.7102073e+08 | M6: 45661483 | N6: Above pace
A7: Aviation | B7: Airport Operating Fund | C7: 444931718 | D7: 2.2714501e+08 | E7: 1765 | F7: 75 | G7: 3.3369879e+08 | H7: 2.1778671e+08 | I7: 51.051656 | J7: -1.0655378e+08 | K7: -23.948344 | L7: 3.0286001e+08 | M7: -1.420717e+08 | N7: Below pace
A8: Austin Water | B8: Austin Water Water Utility Operating Fund | C8: 433874052 | D8: 3.2684893e+08 | E8: 3594 | F8: 75 | G8: 325405539 | H8: 1.0702512e+08 | I8: 75.332674 | J8: 1443388.3 | K8: 0.33267449 | L8: 4.3579857e+08 | M8: 1924517.7 | N8: Near pace
A9: Austin Water | B9: Austin Water Wastewater Utility Operating Fund | C9: 412858853 | D9: 3.2983873e+08 | E9: 3237 | F9: 75 | G9: 3.0964414e+08 | H9: 83020126 | I9: 79.891402 | J9: 20194587 | K9: 4.8914022 | L9: 4.3978497e+08 | M9: 26926116 | N9: Near pace
A10: Human Resources | B10: Employee Benefits Fund | C10: 332107330 | D10: 2.8593591e+08 | E10: 81 | F10: 75 | G10: 2.490805e+08 | H10: 46171424 | I10: 86.097439 | J10: 36855408 | K10: 11.097439 | L10: 3.8124787e+08 | M10: 49140545 | N10: Above pace
A11: General Obligation Debt Service | B11: General Obligation Debt Service Fund | C11: 283490710 | D11: 78685419 | E11: 4 | F11: 75 | G11: 2.1261803e+08 | H11: 2.0480529e+08 | I11: 27.755907 | J11: -1.3393261e+08 | K11: -47.244093 | L11: 1.0491389e+08 | M11: -1.7857682e+08 | N11: Below pace
A12: Fire | B12: General Fund | C12: 269064011 | D12: 2.2783841e+08 | E12: 1616 | F12: 75 | G12: 2.0179801e+08 | H12: 41225601 | I12: 84.678144 | J12: 26040402 | K12: 9.6781437 | L12: 3.0378455e+08 | M12: 34720536 | N12: Above pace
A13: Enterprise Debt Service | B13: AWU Debt Service Fund | C13: 225161708 | D13: 2.1422039e+08 | E13: 4 | F13: 75 | G13: 168871281 | H13: 10941314 | I13: 95.140686 | J13: 45349113 | K13: 20.140686 | L13: 2.8562719e+08 | M13: 60465484 | N13: Above pace
A14: Austin Energy | B14: E-Elec Short Trm Debt Clearing | C14: 223938407 | D14: 126990000 | E14: 1 | F14: 75 | G14: 1.6795381e+08 | H14: 96948407 | I14: 56.707557 | J14: -40963805 | K14: -18.292443 | L14: 169320000 | M14: -54618407 | N14: Below pace
A15: Public Works | B15: Transportation Fund | C15: 213402629 | D15: 1.5839115e+08 | E15: 2391 | F15: 75 | G15: 1.6005197e+08 | H15: 55011476 | I15: 74.221744 | J15: -1660818.5 | K15: -0.77825588 | L15: 2.111882e+08 | M15: -2214424.7 | N15: Near pace
A16: Nondepartmental | B16: Project Connect Fund | C16: 187483362 | D16: 1.842155e+08 | E16: 2 | F16: 75 | G16: 1.4061252e+08 | H16: 3267861 | I16: 98.256986 | J16: 43602980 | K16: 23.256986 | L16: 2.4562067e+08 | M16: 58137306 | N16: Above pace
... A168: Fire | B168: Fire Miscellaneous | C168: 7000 | D168: 0 | E168: 2 | F168: 75 | G168: 5250 | H168: 7000 | I168: 0 | J168: -5250 | K168: -75 | L168: 0 | M168: -7000 | N168: Below pace
A169: Austin Resource Recovery | B169: ARR-Austin Resource Recovery Cip | C169: 0 | D169: 0 | E169: 11 | F169: 75 | G169: 0 | H169: 0 | J169: 0 | L169: 0 | M169: 0 | N169: Review: non-positive budget
A170: Austin Public Library | B170: General Fund Budget Stabilization Reserve Fund | C170: 0 | D170: 0 | E170: 2 | F170: 75 | G170: 0 | H170: 0 | J170: 0 | L170: 0 | M170: 0 | N170: Review: non-positive budget
A171: Austin Public Library | B171: Friends of APL | C171: 0 | D171: 0 | E171: 4 | F171: 75 | G171: 0 | H171: 0 | J171: 0 | L171: 0 | M171: 0 | N171: Review: non-positive budget
A172: Animal Services | B172: General Fund Budget Stabilization Reserve Fund | C172: 0 | D172: 0 | E172: 1 | F172: 75 | G172: 0 | H172: 0 | J172: 0 | L172: 0 | M172: 0 | N172: Review: non-positive budget
A173: Communications & Technology Management | B173: Radio Inventory | C173: 0 | D173: 15071.8 | E173: 1 | F173: 75 | G173: 0 | H173: -15071.8 | J173: 15071.8 | L173: 20095.733 | M173: 20095.733 | N173: Review: spend without budget
A174: Development Services | B174: Urban Forest Replenishment Fund | C174: 0 | D174: -4596.62 | E174: 12 | F174: 75 | G174: 0 | H174: 4596.62 | J174: -4596.62 | L174: -6128.8267 | M174: -6128.8267 | N174: Review: non-positive budget
A175: Economic Development | B175: Childcare Assistance Reserve Fund | C175: 0 | D175: 0 | E175: 1 | F175: 75 | G175: 0 | H175: 0 | J175: 0 | L175: 0 | M175: 0 | N175: Review: non-positive budget
A176: Economic Development | B176: Cultural Arts Fund | C176: 0 | D176: 0 | E176: 13 | F176: 75 | G176: 0 | H176: 0 | J176: 0 | L176: 0 | M176: 0 | N176: Review: non-positive budget
A177: Communications & Public Information | B177: Support Services Fund | C177: 0 | D177: 0 | E177: 306 | F177: 75 | G177: 0 | H177: 0 | J177: 0 | L177: 0 | M177: 0 | N177: Review: non-positive budget
A178: Aviation | B178: Mueller Airport Disposition Fd | C178: 0 | D178: 6460.16 | E178: 1 | F178: 75 | G178: 0 | H178: -6460.16 | J178: 6460.16 | L178: 8613.5467 | M178: 8613.5467 | N178: Review: spend without budget
A179: Communications & Public Information | B179: General Fund Budget Stabilization Reserve Fund | C179: 0 | D179: 0 | E179: 6 | F179: 75 | G179: 0 | H179: 0 | J179: 0 | L179: 0 | M179: 0 | N179: Review: non-positive budget
A180: Austin Public Health | B180: General Fund Budget Stabilization Reserve Fund | C180: 0 | D180: 0 | E180: 3 | F180: 75 | G180: 0 | H180: 0 | J180: 0 | L180: 0 | M180: 0 | N180: Review: non-positive budget
... A216: Public Works | B216: GCP-Transportation PB/2020 | C216: 0 | D216: 0 | E216: 1 | F216: 75 | G216: 0 | H216: 0 | J216: 0 | L216: 0 | M216: 0 | N216: Review: non-positive budget

Sheet Variance_Drivers
A1: Variance Drivers
A2: Reviewed output generated by build_finance.py.
A4: dept_rollup_name | B4: fund_name | C4: program_name | D4: expense_category | E4: budget | F4: expenditures | G4: source_lines | H4: elapsed_pct | I4: expected_spend_to_date | J4: remaining_budget | K4: utilization_pct | L4: pace_variance | M4: pace_gap_pct_points | N4: linear_run_rate_proxy | O4: projected_variance_proxy | P4: pace_status | Q4: absolute_pace_variance
A5: General Obligation Debt Service | B5: General Obligation Debt Service Fund | C5: Transfers and Other Requirements | D5: Transfers & debt service | E5: 281460710 | F5: 77014206 | G5: 2 | H5: 75 | I5: 2.1109553e+08 | J5: 2.044465e+08 | K5: 27.362329 | L5: -1.3408133e+08 | M5: -47.637671 | N5: 1.0268561e+08 | O5: -1.787751e+08 | P5: Below pace | Q5: 1.3408133e+08
A6: Aviation | B6: Airport Operating Fund | C6: Transfers, Debt Service, and Other Requirements | D6: Transfers & debt service | E6: 238306905 | F6: 71648227 | G6: 7 | H6: 75 | I6: 1.7873018e+08 | J6: 1.6665868e+08 | K6: 30.065527 | L6: -1.0708195e+08 | M6: -44.934473 | N6: 95530970 | O6: -1.4277594e+08 | P6: Below pace | Q6: 1.0708195e+08
A7: Nondepartmental | B7: Hotel Occupancy Tax Fund | C7: Transfers, Debt Service, and Other Requirements | D7: Transfers & debt service | E7: 167288265 | F7: 1.7228288e+08 | G7: 6 | H7: 75 | I7: 1.254662e+08 | J7: -4994616.9 | K7: 102.98563 | L7: 46816683 | M7: 27.985635 | N7: 2.2971051e+08 | O7: 62422244 | P7: Above pace | Q7: 46816683
A8: Enterprise Debt Service | B8: AWU Debt Service Fund | C8: Transfers, Debt Service, and Other Requirements | D8: Transfers & debt service | E8: 225161708 | F8: 2.1422039e+08 | G8: 4 | H8: 75 | I8: 168871281 | J8: 10941314 | K8: 95.140686 | L8: 45349113 | M8: 20.140686 | N8: 2.8562719e+08 | O8: 60465484 | P8: Above pace | Q8: 45349113
A9: Enterprise Debt Service | B9: AE Debt Service Fund | C9: Transfers, Debt Service, and Other Requirements | D9: Transfers & debt service | E9: 174097715 | F9: 1.7473698e+08 | G9: 2 | H9: 75 | I9: 1.3057329e+08 | J9: -639261.86 | K9: 100.36719 | L9: 44163691 | M9: 25.367186 | N9: 2.3298264e+08 | O9: 58884921 | P9: Above pace | Q9: 44163691
A10: Nondepartmental | B10: Project Connect Fund | C10: Division Placeholder | D10: Contractual services | E10: 186681064 | F10: 1.8354692e+08 | G10: 1 | H10: 75 | I10: 140010798 | J10: 3134144.7 | K10: 98.321123 | L10: 43536121 | M10: 23.321123 | N10: 2.4472923e+08 | O10: 58048162 | P10: Above pace | Q10: 43536121
A11: Austin Energy | B11: E-Elec Short Trm Debt Clearing | C11: Electric Cip Transfers To | D11: Transfers & debt service | E11: 223938407 | F11: 126990000 | G11: 1 | H11: 75 | I11: 1.6795381e+08 | J11: 96948407 | K11: 56.707557 | L11: -40963805 | M11: -18.292443 | N11: 169320000 | O11: -54618407 | P11: Below pace | Q11: 40963805
A12: Human Resources | B12: Employee Benefits Fund | C12: Employee Medical | D12: Personnel & benefits | E12: 169271849 | F12: 1.525993e+08 | G12: 3 | H12: 75 | I12: 1.2695389e+08 | J12: 16672551 | K12: 90.150429 | L12: 25645411 | M12: 15.150429 | N12: 2.0346573e+08 | O12: 34193881 | P12: Above pace | Q12: 25645411
A13: Enterprise Debt Service | B13: Airport Revenue Bond Redemption Fund | C13: Transfers, Debt Service, and Other Requirements | D13: Transfers & debt service | E13: 104909375 | F13: 1.0392105e+08 | G13: 2 | H13: 75 | I13: 78682031 | J13: 988326.38 | K13: 99.057924 | L13: 25239017 | M13: 24.057924 | N13: 1.385614e+08 | O13: 33652023 | P13: Above pace | Q13: 25239017
A14: Austin Convention Center | B14: Tourism Public Improvement District | C14: Public Improvement District | D14: Contractual services | E14: 27878795 | F14: 0 | G14: 1 | H14: 75 | I14: 20909096 | J14: 27878795 | K14: 0 | L14: -20909096 | M14: -75 | N14: 0 | O14: -27878795 | P14: Below pace | Q14: 20909096
A15: Austin Energy | B15: Austin Energy Fund | C15: Support Services | D15: Other operating costs | E15: 12135494 | F15: -10677469 | G15: 962 | H15: 75 | I15: 9101620.5 | J15: 22812963 | K15: -87.985453 | L15: -19779090 | M15: -162.98545 | N15: -14236626 | O15: -26372120 | P15: Below pace | Q15: 19779090
A16: Austin Energy | B16: Austin Energy Fund | C16: Transfers, Debt Service, and Other Requirements | D16: Transfers & debt service | E16: 479629401 | F16: 3.7938861e+08 | G16: 12 | H16: 75 | I16: 3.5972205e+08 | J16: 1.0024079e+08 | K16: 79.100367 | L16: 19666564 | M16: 4.1003666 | N16: 5.0585149e+08 | O16: 26222085 | P16: Near pace | Q16: 19666564
... A20: Enterprise Debt Service | B20: Convention Center HOT Debt Service Fund-Subordinate Lien | C20: Transfers, Debt Service, and Other Requirements | D20: Transfers & debt service | E20: 30320995 | F20: 7997935.5 | G20: 3 | H20: 75 | I20: 22740746 | J20: 22323060 | K20: 26.377549 | L20: -14742811 | M20: -48.622451 | N20: 10663914 | O20: -19657081 | P20: Below pace | Q20: 14742811
A21: Austin Convention Center | B21: Tourism Public Improvement District | C21: Public Improvement District | D21: Grants & contributions | E21: 0 | F21: 13917856 | G21: 1 | H21: 75 | I21: 0 | J21: -13917856 | L21: 13917856 | N21: 18557141 | O21: 18557141 | P21: Review: spend without budget | Q21: 13917856
A22: Enterprise Debt Service | B22: Convention Center Expansion Senior Lien Debt Service Fund | C22: Transfers, Debt Service, and Other Requirements | D22: Transfers & debt service | E22: 17858638 | F22: 0 | G22: 2 | H22: 75 | I22: 13393978 | J22: 17858638 | K22: 0 | L22: -13393978 | M22: -75 | N22: 0 | O22: -17858638 | P22: Below pace | Q22: 13393978
A23: Austin Energy | B23: Austin Energy Fund | C23: Power Supply | D23: Supplies, technology & equipment | E23: 0 | F23: 13265401 | G23: 1 | H23: 75 | I23: 0 | J23: -13265401 | L23: 13265401 | N23: 17687201 | O23: 17687201 | P23: Review: spend without budget | Q23: 13265401
A24: Fire | B24: General Fund | C24: Fire / Emergency Response | D24: Personnel & benefits | E24: 129669201 | F24: 1.0861977e+08 | G24: 47 | H24: 75 | I24: 97251901 | J24: 21049432 | K24: 83.766822 | L24: 11367868 | M24: 8.7668223 | N24: 1.4482636e+08 | O24: 15157158 | P24: Above pace | Q24: 11367868
A25: Homeless Strategy Office | B25: General Fund | C25: Social Service Grants - HSO | D25: Grants & contributions | E25: 39492782 | F25: 18458747 | G25: 2 | H25: 75 | I25: 29619586 | J25: 21034035 | K25: 46.739546 | L25: -11160839 | M25: -28.260454 | N25: 24611663 | O25: -14881119 | P25: Below pace | Q25: 11160839
A26: Office of Arts, Culture, Music and Entertainment | B26: Historic Preservation Fund | C26: Cultural Education and Heritage Preservation | D26: Other operating costs | E26: 15645780 | F26: 1857778 | G26: 5 | H26: 75 | I26: 11734335 | J26: 13788002 | K26: 11.873988 | L26: -9876557 | M26: -63.126012 | N26: 2477037.3 | O26: -13168743 | P26: Below pace | Q26: 9876557
A27: Austin Energy | B27: Austin Energy Fund | C27: Electric System | D27: Contractual services | E27: 269981957 | F27: 2.122074e+08 | G27: 208 | H27: 75 | I27: 2.0248647e+08 | J27: 57774556 | K27: 78.600586 | L27: 9720933.4 | M27: 3.6005863 | N27: 2.829432e+08 | O27: 12961245 | P27: Near pace | Q27: 9720933.4
A28: Austin Energy | B28: Austin Energy Fund | C28: Customer Care | D28: Contractual services | E28: 38063936 | F28: 19679646 | G28: 82 | H28: 75 | I28: 28547952 | J28: 18384290 | K28: 51.701552 | L28: -8868306.4 | M28: -23.298448 | N28: 26239527 | O28: -11824409 | P28: Below pace | Q28: 8868306.4
A29: Austin Water | B29: Austin Water Wastewater Utility Operating Fund | C29: Transfers, Debt Service, and Other Requirements | D29: Transfers & debt service | E29: 224880632 | F29: 1.7686525e+08 | G29: 12 | H29: 75 | I29: 168660474 | J29: 48015387 | K29: 78.648501 | L29: 8204771.1 | M29: 3.6485006 | N29: 2.3582033e+08 | O29: 10939695 | P29: Near pace | Q29: 8204771.1
A30: Austin Water | B30: Austin Water Water Utility Operating Fund | C30: Transfers, Debt Service, and Other Requirements | D30: Transfers & debt service | E30: 208413427 | F30: 1.6433484e+08 | G30: 14 | H30: 75 | I30: 1.5631007e+08 | J30: 44078592 | K30: 78.850407 | L30: 8024765.2 | M30: 3.850407 | N30: 2.1911311e+08 | O30: 10699687 | P30: Near pace | Q30: 8024765.2
A31: Financial Services | B31: Downtown Public Improvement District Fund | C31: Public Improvement District | D31: Contractual services | E31: 14274964 | F31: 3229714.8 | G31: 3 | H31: 75 | I31: 10706223 | J31: 11045249 | K31: 22.62503 | L31: -7476508.2 | M31: -52.37497 | N31: 4306286.4 | O31: -9968677.6 | P31: Below pace | Q31: 7476508.2
A32: Austin Energy | B32: Austin Energy Fund | C32: Electric System | D32: Personnel & benefits | E32: 105010315 | F32: 85979578 | G32: 573 | H32: 75 | I32: 78757736 | J32: 19030737 | K32: 81.877269 | L32: 7221841.7 | M32: 6.8772689 | N32: 1.1463944e+08 | O32: 9629122.3 | P32: Above pace | Q32: 7221841.7
A33: Austin Convention Center | B33: Convention Center Capital Fund | C33: Transfers, Debt Service, and Other Requirements | D33: Transfers & debt service | E33: 37306706 | F33: 20858638 | G33: 2 | H33: 75 | I33: 27980030 | J33: 16448068 | K33: 55.911229 | L33: -7121391.5 | M33: -19.088771 | N33: 27811517 | O33: -9495188.7 | P33: Below pace | Q33: 7121391.5
A34: Office of Arts, Culture, Music and Entertainment | B34: Cultural Arts Fund | C34: Cultural Arts | D34: Grants & contributions | E34: 14932838 | F34: 4107424.8 | G34: 8 | H34: 75 | I34: 11199628 | J34: 10825413 | K34: 27.505989 | L34: -7092203.8 | M34: -47.494011 | N34: 5476566.3 | O34: -9456271.7 | P34: Below pace | Q34: 7092203.8
A35: Fire | B35: General Fund | C35: Fire / Emergency Response | D35: Other operating costs | E35: 8942594 | F35: 13768717 | G35: 211 | H35: 75 | I35: 6706945.5 | J35: -4826123.4 | K35: 153.96782 | L35: 7061771.9 | M35: 78.967824 | N35: 18358290 | O35: 9415695.9 | P35: Above pace | Q35: 7061771.9
... A45: Police | B45: General Fund | C45: Transfers, Debt Service, and Other Requirements | D45: Other operating costs | E45: 53010117 | F45: 44154100 | G45: 12 | H45: 75 | I45: 39757588 | J45: 8856017.1 | K45: 83.293723 | L45: 4396512.1 | M45: 8.2937228 | N45: 58872133 | O45: 5862016.2 | P45: Above pace | Q45: 4396512.1
A46: Homeless Strategy Office | B46: Neighborhood Housing-Housing Trust Fund | C46: Homeless Diversion Services | D46: Other operating costs | E46: 0 | F46: 4279899.1 | G46: 2 | H46: 75 | I46: 0 | J46: -4279899.1 | L46: 4279899.1 | N46: 5706532.1 | O46: 5706532.1 | P46: Review: spend without budget | Q46: 4279899.1
A47: Austin Water | B47: Austin Water Wastewater Utility Operating Fund | C47: Support Services | D47: Personnel & benefits | E47: 18838411 | F47: 18286036 | G47: 297 | H47: 75 | I47: 14128808 | J47: 552374.93 | K47: 97.067826 | L47: 4157227.8 | M47: 22.067826 | N47: 24381381 | O47: 5542970.4 | P47: Above pace | Q47: 4157227.8
A48: Austin Energy | B48: Austin Energy Fund | C48: Customer Care | D48: Personnel & benefits | E48: 51002653 | F48: 42386866 | G48: 386 | H48: 75 | I48: 38251990 | J48: 8615786.5 | K48: 83.10718 | L48: 4134876.8 | M48: 8.1071797 | N48: 56515822 | O48: 5513169 | P48: Above pace | Q48: 4134876.8
A49: Police | B49: General Fund | C49: Neighborhood-Based Policing | D49: Personnel & benefits | E49: 161473310 | F49: 1.2511116e+08 | G49: 414 | H49: 75 | I49: 1.2110498e+08 | J49: 36362155 | K49: 77.481012 | L49: 4006172.6 | M49: 2.4810123 | N49: 1.6681487e+08 | O49: 5341563.5 | P49: Near pace | Q49: 4006172.6
A50: Law | B50: Liability Reserve Fund | C50: Liability Reserve | D50: Other operating costs | E50: 6801000 | F50: 1104762.4 | G50: 67 | H50: 75 | I50: 5100750 | J50: 5696237.6 | K50: 16.244117 | L50: -3995987.6 | M50: -58.755883 | N50: 1473016.6 | O50: -5327983.4 | P50: Below pace | Q50: 3995987.6
A51: Austin Convention Center | B51: Convention Center Operating Fund | C51: Transfers, Debt Service, and Other Requirements | D51: Transfers & debt service | E51: 27431442 | F51: 24535830 | G51: 8 | H51: 75 | I51: 20573582 | J51: 2895611.9 | K51: 89.444186 | L51: 3962248.6 | M51: 14.444186 | N51: 32714440 | O51: 5282998.1 | P51: Above pace | Q51: 3962248.6
A52: Homeless Strategy Office | B52: Neighborhood Housing-Housing Trust Fund | C52: Homeless Diversion Services | D52: Grants & contributions | E52: 5057474 | F52: 0 | G52: 2 | H52: 75 | I52: 3793105.5 | J52: 5057474 | K52: 0 | L52: -3793105.5 | M52: -75 | N52: 0 | O52: -5057474 | P52: Below pace | Q52: 3793105.5
A53: Neighborhood Housing & Community Development | B53: Neighborhood Housing University Neighborhood Overlay Fund | C53: Housing | D53: Grants & contributions | E53: 4956769 | F53: 0 | G53: 2 | H53: 75 | I53: 3717576.8 | J53: 4956769 | K53: 0 | L53: -3717576.8 | M53: -75 | N53: 0 | O53: -4956769 | P53: Below pace | Q53: 3717576.8
...

Sheet Data_Quality
A1: Data Quality
A2: Reviewed output generated by build_finance.py.
A4: check_name | B4: issue_count | C4: check_status
A5: source_rows | B5: 57267 | C5: INFO
A6: duplicate_key_rows | B6: 0 | C6: PASS
A7: missing_dimension_cells | B7: 0 | C7: PASS
A8: zero_budget_rows | B8: 26552 | C8: REVIEW
A9: positive_spend_with_zero_budget_rows | B9: 13688 | C9: REVIEW
A10: positive_spend_with_zero_budget_value | B10: 4.351942e+08 | C10: REVIEW
A11: negative_budget_rows | B11: 1242 | C11: REVIEW
A12: negative_expenditure_rows | B12: 768 | C12: REVIEW
A13: fiscal_year_values | B13: 1 | C13: PASS
A14: through_quarter_values | B14: 1 | C14: PASS

Sheet Scenario_Assumptions
A1: CORPORATE SCENARIO ASSUMPTIONS
A2: Yellow cells are editable. Adjustments apply only to forecast months August–December 2026.
A4: Revenue adjustment | B4: 0 | C4: Applied to future revenue
A5: Cost inflation | B5: 0 | C5: Applied to future COGS and operating expense
A6: Hiring-delay savings | B6: 0 | C6: Offsets future Product & Engineering and G&A costs

Sheet Corporate_Plan
A1: SYNTHETIC CORPORATE PLAN
A2: Seeded demonstration only. Scenario Amount and P&L Variance are formula-driven from Scenario_Assumptions.
A4: Month | B4: Period Status | C4: Business Unit | D4: Statement Group | E4: Line Item | F4: Budget Amount | G4: Actual Amount | H4: Base Forecast Amount | I4: Scenario Amount | J4: P&L Variance to Budget
A5: 2026-01-01 | B5: Actual | C5: Enterprise | D5: Revenue | E5: Subscription revenue | F5: 5280000 | G5: 5188222.7 | H5: 5188222.7 | I5: =IF(B5="Actual",H5,IF(D5="Revenue",H5*(1+Scenario_Assumptions!$B$4),H5*(1+Scenario_Assumptions!$B$5)*IF(OR(E5="Product & engineering",E5="General & administrative"),1-Scenario_Assumptions!$B$6,1))) | J5: =(I5-F5)*IF(D5="Revenue",1,-1)
A6: 2026-01-01 | B6: Actual | C6: Enterprise | D6: Revenue | E6: Professional services revenue | F6: 1188000 | G6: 1168992.5 | H6: 1168992.5 | I6: =IF(B6="Actual",H6,IF(D6="Revenue",H6*(1+Scenario_Assumptions!$B$4),H6*(1+Scenario_Assumptions!$B$5)*IF(OR(E6="Product & engineering",E6="General & administrative"),1-Scenario_Assumptions!$B$6,1))) | J6: =(I6-F6)*IF(D6="Revenue",1,-1)
A7: 2026-01-01 | B7: Actual | C7: Enterprise | D7: COGS | E7: Cloud hosting | F7: 858330 | G7: 921641.52 | H7: 921641.52 | I7: =IF(B7="Actual",H7,IF(D7="Revenue",H7*(1+Scenario_Assumptions!$B$4),H7*(1+Scenario_Assumptions!$B$5)*IF(OR(E7="Product & engineering",E7="General & administrative"),1-Scenario_Assumptions!$B$6,1))) | J7: =(I7-F7)*IF(D7="Revenue",1,-1)
A8: 2026-01-01 | B8: Actual | C8: Enterprise | D8: COGS | E8: Customer support delivery | F8: 412335 | G8: 432339.07 | H8: 432339.07 | I8: =IF(B8="Actual",H8,IF(D8="Revenue",H8*(1+Scenario_Assumptions!$B$4),H8*(1+Scenario_Assumptions!$B$5)*IF(OR(E8="Product & engineering",E8="General & administrative"),1-Scenario_Assumptions!$B$6,1))) | J8: =(I8-F8)*IF(D8="Revenue",1,-1)
A9: 2026-01-01 | B9: Actual | C9: Enterprise | D9: Operating expense | E9: Sales & marketing | F9: 1312740 | G9: 1347165.4 | H9: 1347165.4 | I9: =IF(B9="Actual",H9,IF(D9="Revenue",H9*(1+Scenario_Assumptions!$B$4),H9*(1+Scenario_Assumptions!$B$5)*IF(OR(E9="Product & engineering",E9="General & administrative"),1-Scenario_Assumptions!$B$6,1))) | J9: =(I9-F9)*IF(D9="Revenue",1,-1)
A10: 2026-01-01 | B10: Actual | C10: Enterprise | D10: Operating expense | E10: Product & engineering | F10: 1571585.4 | G10: 1575428.7 | H10: 1575428.7 | I10: =IF(B10="Actual",H10,IF(D10="Revenue",H10*(1+Scenario_Assumptions!$B$4),H10*(1+Scenario_Assumptions!$B$5)*IF(OR(E10="Product & engineering",E10="General & administrative"),1-Scenario_Assumptions!$B$6,1))) | J10: =(I10-F10)*IF(D10="Revenue",1,-1)
A11: 2026-01-01 | B11: Actual | C11: Enterprise | D11: Operating expense | E11: General & administrative | F11: 723690 | G11: 722384.47 | H11: 722384.47 | I11: =IF(B11="Actual",H11,IF(D11="Revenue",H11*(1+Scenario_Assumptions!$B$4),H11*(1+Scenario_Assumptions!$B$5)*IF(OR(E11="Product & engineering",E11="General & administrative"),1-Scenario_Assumptions!$B$6,1))) | J11: =(I11-F11)*IF(D11="Revenue",1,-1)
A12: 2026-01-01 | B12: Actual | C12: SMB | D12: Revenue | E12: Subscription revenue | F12: 3200000 | G12: 3094700.6 | H12: 3094700.6 | I12: =IF(B12="Actual",H12,IF(D12="Revenue",H12*(1+Scenario_Assumptions!$B$4),H12*(1+Scenario_Assumptions!$B$5)*IF(OR(E12="Product & engineering",E12="General & administrative"),1-Scenario_Assumptions!$B$6,1))) | J12: =(I12-F12)*IF(D12="Revenue",1,-1)
A13: 2026-01-01 | B13: Actual | C13: SMB | D13: Revenue | E13: Professional services revenue | F13: 720000 | G13: 726897.58 | H13: 726897.58 | I13: =IF(B13="Actual",H13,IF(D13="Revenue",H13*(1+Scenario_Assumptions!$B$4),H13*(1+Scenario_Assumptions!$B$5)*IF(OR(E13="Product & engineering",E13="General & administrative"),1-Scenario_Assumptions!$B$6,1))) | J13: =(I13-F13)*IF(D13="Revenue",1,-1)
A14: 2026-01-01 | B14: Actual | C14: SMB | D14: COGS | E14: Cloud hosting | F14: 520200 | G14: 537717.16 | H14: 537717.16 | I14: =IF(B14="Actual",H14,IF(D14="Revenue",H14*(1+Scenario_Assumptions!$B$4),H14*(1+Scenario_Assumptions!$B$5)*IF(OR(E14="Product & engineering",E14="General & administrative"),1-Scenario_Assumptions!$B$6,1))) | J14: =(I14-F14)*IF(D14="Revenue",1,-1)
A15: 2026-01-01 | B15: Actual | C15: SMB | D15: COGS | E15: Customer support delivery | F15: 249900 | G15: 261641.54 | H15: 261641.54 | I15: =IF(B15="Actual",H15,IF(D15="Revenue",H15*(1+Scenario_Assumptions!$B$4),H15*(1+Scenario_Assumptions!$B$5)*IF(OR(E15="Product & engineering",E15="General & administrative"),1-Scenario_Assumptions!$B$6,1))) | J15: =(I15-F15)*IF(D15="Revenue",1,-1)
A16: 2026-01-01 | B16: Actual | C16: SMB | D16: Operating expense | E16: Sales & marketing | F16: 795600 | G16: 870740.28 | H16: 870740.28 | I16: =IF(B16="Actual",H16,IF(D16="Revenue",H16*(1+Scenario_Assumptions!$B$4),H16*(1+Scenario_Assumptions!$B$5)*IF(OR(E16="Product & engineering",E16="General & administrative"),1-Scenario_Assumptions!$B$6,1))) | J16: =(I16-F16)*IF(D16="Revenue",1,-1)
... A151: 2026-07-01 | B151: Actual | C151: Customer Solutions | D151: Operating expense | E151: General & administrative | F151: 307020 | G151: 300786.75 | H151: 300786.75 | I151: =IF(B151="Actual",H151,IF(D151="Revenue",H151*(1+Scenario_Assumptions!$B$4),H151*(1+Scenario_Assumptions!$B$5)*IF(OR(E151="Product & engineering",E151="General & administrative"),1-Scenario_Assumptions!$B$6,1))) | J151: =(I151-F151)*IF(D151="Revenue",1,-1)
A152: 2026-08-01 | B152: Forecast | C152: Enterprise | D152: Revenue | E152: Subscription revenue | F152: 5187600 | H152: 5096817 | I152: =IF(B152="Actual",H152,IF(D152="Revenue",H152*(1+Scenario_Assumptions!$B$4),H152*(1+Scenario_Assumptions!$B$5)*IF(OR(E152="Product & engineering",E152="General & administrative"),1-Scenario_Assumptions!$B$6,1))) | J152: =(I152-F152)*IF(D152="Revenue",1,-1)
A153: 2026-08-01 | B153: Forecast | C153: Enterprise | D153: Revenue | E153: Professional services revenue | F153: 1167210 | H153: 1175380.5 | I153: =IF(B153="Actual",H153,IF(D153="Revenue",H153*(1+Scenario_Assumptions!$B$4),H153*(1+Scenario_Assumptions!$B$5)*IF(OR(E153="Product & engineering",E153="General & administrative"),1-Scenario_Assumptions!$B$6,1))) | J153: =(I153-F153)*IF(D153="Revenue",1,-1)
A154: 2026-08-01 | B154: Forecast | C154: Enterprise | D154: COGS | E154: Cloud hosting | F154: 841500 | H154: 873897.75 | I154: =IF(B154="Actual",H154,IF(D154="Revenue",H154*(1+Scenario_Assumptions!$B$4),H154*(1+Scenario_Assumptions!$B$5)*IF(OR(E154="Product & engineering",E154="General & administrative"),1-Scenario_Assumptions!$B$6,1))) | J154: =(I154-F154)*IF(D154="Revenue",1,-1)
A155: 2026-08-01 | B155: Forecast | C155: Enterprise | D155: COGS | E155: Customer support delivery | F155: 404250 | H155: 411324.38 | I155: =IF(B155="Actual",H155,IF(D155="Revenue",H155*(1+Scenario_Assumptions!$B$4),H155*(1+Scenario_Assumptions!$B$5)*IF(OR(E155="Product & engineering",E155="General & administrative"),1-Scenario_Assumptions!$B$6,1))) | J155: =(I155-F155)*IF(D155="Revenue",1,-1)
A156: 2026-08-01 | B156: Forecast | C156: Enterprise | D156: Operating expense | E156: Sales & marketing | F156: 1287000 | H156: 1354567.5 | I156: =IF(B156="Actual",H156,IF(D156="Revenue",H156*(1+Scenario_Assumptions!$B$4),H156*(1+Scenario_Assumptions!$B$5)*IF(OR(E156="Product & engineering",E156="General & administrative"),1-Scenario_Assumptions!$B$6,1))) | J156: =(I156-F156)*IF(D156="Revenue",1,-1)
A157: 2026-08-01 | B157: Forecast | C157: Enterprise | D157: Operating expense | E157: Product & engineering | F157: 1700160 | H157: 1741813.9 | I157: =IF(B157="Actual",H157,IF(D157="Revenue",H157*(1+Scenario_Assumptions!$B$4),H157*(1+Scenario_Assumptions!$B$5)*IF(OR(E157="Product & engineering",E157="General & administrative"),1-Scenario_Assumptions!$B$6,1))) | J157: =(I157-F157)*IF(D157="Revenue",1,-1)
A158: 2026-08-01 | B158: Forecast | C158: Enterprise | D158: Operating expense | E158: General & administrative | F158: 709500 | H158: 707016.75 | I158: =IF(B158="Actual",H158,IF(D158="Revenue",H158*(1+Scenario_Assumptions!$B$4),H158*(1+Scenario_Assumptions!$B$5)*IF(OR(E158="Product & engineering",E158="General & administrative"),1-Scenario_Assumptions!$B$6,1))) | J158: =(I158-F158)*IF(D158="Revenue",1,-1)
A159: 2026-08-01 | B159: Forecast | C159: SMB | D159: Revenue | E159: Subscription revenue | F159: 3144000 | H159: 3088980 | I159: =IF(B159="Actual",H159,IF(D159="Revenue",H159*(1+Scenario_Assumptions!$B$4),H159*(1+Scenario_Assumptions!$B$5)*IF(OR(E159="Product & engineering",E159="General & administrative"),1-Scenario_Assumptions!$B$6,1))) | J159: =(I159-F159)*IF(D159="Revenue",1,-1)
A160: 2026-08-01 | B160: Forecast | C160: SMB | D160: Revenue | E160: Professional services revenue | F160: 707400 | H160: 712351.8 | I160: =IF(B160="Actual",H160,IF(D160="Revenue",H160*(1+Scenario_Assumptions!$B$4),H160*(1+Scenario_Assumptions!$B$5)*IF(OR(E160="Product & engineering",E160="General & administrative"),1-Scenario_Assumptions!$B$6,1))) | J160: =(I160-F160)*IF(D160="Revenue",1,-1)
A161: 2026-08-01 | B161: Forecast | C161: SMB | D161: COGS | E161: Cloud hosting | F161: 510000 | H161: 529635 | I161: =IF(B161="Actual",H161,IF(D161="Revenue",H161*(1+Scenario_Assumptions!$B$4),H161*(1+Scenario_Assumptions!$B$5)*IF(OR(E161="Product & engineering",E161="General & administrative"),1-Scenario_Assumptions!$B$6,1))) | J161: =(I161-F161)*IF(D161="Revenue",1,-1)
A162: 2026-08-01 | B162: Forecast | C162: SMB | D162: COGS | E162: Customer support delivery | F162: 245000 | H162: 249287.5 | I162: =IF(B162="Actual",H162,IF(D162="Revenue",H162*(1+Scenario_Assumptions!$B$4),H162*(1+Scenario_Assumptions!$B$5)*IF(OR(E162="Product & engineering",E162="General & administrative"),1-Scenario_Assumptions!$B$6,1))) | J162: =(I162-F162)*IF(D162="Revenue",1,-1)
A163: 2026-08-01 | B163: Forecast | C163: SMB | D163: Operating expense | E163: Sales & marketing | F163: 780000 | H163: 820950 | I163: =IF(B163="Actual",H163,IF(D163="Revenue",H163*(1+Scenario_Assumptions!$B$4),H163*(1+Scenario_Assumptions!$B$5)*IF(OR(E163="Product & engineering",E163="General & administrative"),1-Scenario_Assumptions!$B$6,1))) | J163: =(I163-F163)*IF(D163="Revenue",1,-1)
... A256: 2026-12-01 | B256: Forecast | C256: Customer Solutions | D256: Operating expense | E256: General & administrative | F256: 301000 | H256: 299946.5 | I256: =IF(B256="Actual",H256,IF(D256="Revenue",H256*(1+Scenario_Assumptions!$B$4),H256*(1+Scenario_Assumptions!$B$5)*IF(OR(E256="Product & engineering",E256="General & administrative"),1-Scenario_Assumptions!$B$6,1))) | J256: =(I256-F256)*IF(D256="Revenue",1,-1)

Sheet Corporate_Dashboard
A1: SYNTHETIC CORPORATE FP&A DASHBOARD
A2: Formula-driven annual plan and scenario view. Change assumptions to test revenue, inflation, and hiring timing.
A4: Budget revenue | B4: =SUMIFS(Corporate_Plan!$F:$F,Corporate_Plan!$D:$D,"Revenue")
A5: Scenario revenue | B5: =SUMIFS(Corporate_Plan!$I:$I,Corporate_Plan!$D:$D,"Revenue")
A6: Budget costs | B6: =SUMIFS(Corporate_Plan!$F:$F,Corporate_Plan!$D:$D,"<>Revenue")
A7: Scenario costs | B7: =SUMIFS(Corporate_Plan!$I:$I,Corporate_Plan!$D:$D,"<>Revenue")
A8: Budget EBITDA | B8: =B4-B6
A9: Scenario EBITDA | B9: =B5-B7
A10: Scenario EBITDA margin | B10: =IFERROR(B9/B5,0)
A13: Month | B13: Budget EBITDA | C13: Base Forecast EBITDA
A14: 2026-01-01 | B14: 3226800.4 | C14: 2615139.6
A15: 2026-02-01 | B15: 3604600 | C15: 2967120.4
A16: 2026-03-01 | B16: 3726602.6 | C16: 2993033.2
A17: 2026-04-01 | B17: 3741950 | C17: 3047648.7
A18: 2026-05-01 | B18: 3634142.6 | C18: 2633309.9
A19: 2026-06-01 | B19: 3419680 | C19: 2098470.4
A20: 2026-07-01 | B20: 2943872.8 | C20: 2429549.9
A21: 2026-08-01 | B21: 2867600 | C21: 2403020.3
A22: 2026-09-01 | B22: 2653137.4 | C22: 2189612.1
A23: 2026-10-01 | B23: 3727210 | C23: 3247988.1
A24: 2026-11-01 | B24: 3742557.4 | C24: 3261402.4
A25: 2026-12-01 | B25: 3864560 | C25: 3380085.3
